#РПМ #Конспект #Программирование #Java 

Отдельно рассмотрим рекурсивные функции. Главное отличие рекурсивных функций от обычных методов состоит в том, что они рекурсивная функция может вызывать саму себя.

Например, рассмотрим функцию, которая вычисляет факториал числа:

```java
static int factorial(int x){

    if (x == 1){

        return 1;

    }

    return x * factorial(x - 1);

}
```

Вначале проверяется условие: если вводимое число не равно 1, то мы умножаем данное число на результат этой же функции, в которую в качестве параметра передается число x-1. То есть происходит рекурсивный спуск. И так дальше, пока не дойдем того момента, когда значение параметра не будет равно единице.

Рекурсивная функция обязательно должна иметь некоторый базовый вариант, который использует оператор return и который помещается в начале функции. В случае с факториалом это if (x == 1) return 1;. И все рекурсивные вызовы должны обращаться к подфункциям, которые в конечном счете сходятся к базовому варианту. Так, при передаче в функцию положительного числа при дальнейших рекурсивных вызовах подфункций в них будет передаваться каждый раз число, меньшее на единицу. И в конце концов мы дойдем до ситуации, когда число будет равно 1, и будет использован базовый вариант.

Хотя в данном случае нужно отметить, что для определения факториала есть более оптимальные решения на основе циклов:

```java
static int factorial(int x){

    int result=1;

    for (int i = 1; i <= x; i++)

    {

        result *= i;

    }

    return  result;

}
```

Еще одним распространенным примером рекурсивной функции служит функция, вычисляющая числа Фибоначчи. В теории n-й член последовательности Фибоначчи определяется по формуле: f(n)=f(n-1) + f(n-2), причем f(0)=0, а f(1)=1.

```java
static int fibonachi(int n){

    if (n == 0){

        return 0;

    }

    if (n == 1){

        return 1;

    }

    else{

        return fibonachi(n - 1) + fibonachi(n - 2);

    }

}
```

**Введение в обработку исключений**

Нередко в процессе выполнения программы могут возникать ошибки, при том необязательно по вине разработчика. Некоторые из них трудно предусмотреть или предвидеть, а иногда и вовсе невозможно. Так, например, может неожиданно оборваться сетевое подключение при передаче файла. Подобные ситуации называются **исключениями**.

В языке Java предусмотрены специальные средства для обработки подобных ситуаций. Одним из таких средств является конструкция **try...catch...finally**. При возникновении исключения в блоке try управление переходит в блок catch, который может обработать данное исключение. Если такого блока не найдено, то пользователю отображается сообщение о необработанном исключении, а дальнейшее выполнение программы останавливается. И чтобы подобной остановки не произошло, и надо использовать блок try..catch. Например:

```java
int[] numbers = new int[3];

numbers[4]=45;

System.out.println(numbers[4]);
```

Так как у нас массив numbers может содержать только 3 элемента, то при выполнении инструкции numbers[4]=45 консоль отобразит исключение, и выполнение программы будет завершено. Теперь попробуем обработать это исключение:

```java
try{

    int[] numbers = new int[3];

    numbers[4]=45;

    System.out.println(numbers[4]);

}

catch(Exception ex){

    ex.printStackTrace();

}

System.out.println("Программа завершена");
```

При использовании блока **try...catch** вначале выполняются все инструкции между операторами try и catch. Если в блоке try вдруг возникает исключение, то обычный порядок выполнения останавливается и переходит к инструкции сatch. Поэтому когда выполнение программы дойдет до строки numbers[4]=45;, программа остановится и перейдет к блоку catch

Выражение **catch** имеет следующий синтаксис: catch (тип_исключения имя_переменной). В данном случае объявляется переменная ex, которая имеет тип Exception. Но если возникшее исключение не является исключением типа, указанного в инструкции сatch, то оно не обрабатывается, а программа просто зависает или выбрасывает сообщение об ошибке.

Но так как тип Exception является базовым классом для всех исключений, то выражение catch (Exception ex) будет обрабатывать практически все исключения. Обработка же исключения в данном случае сводится к выводу на консоль стека трассировки ошибки с помощью метода printStackTrace(), определенного в классе Exception.

После завершения выполнения блока catch программа продолжает свою работу, выполняя все остальные инструкции после блока catch.

Конструкция try..catch также может иметь блок finally. Однако этот блок необязательный, и его можно при обработке исключений опускать. Блок finally выполняется в любом случае, возникло ли исключение в блоке try или нет:

```java
try{

    int[] numbers = new int[3];

    numbers[4]=45;

    System.out.println(numbers[4]);

}

catch(Exception ex){

    ex.printStackTrace();

}

finally{

    System.out.println("Блок finally");

}

System.out.println("Программа завершена");
```

**Обработка нескольких исключений**

В Java имеется множество различных типов исключений, и мы можем разграничить их обработку, включив дополнительные блоки catch:

```java
int[] numbers = new int[3];

try{

    numbers[6]=45;

    numbers[6]=Integer.parseInt("gfd");

}

catch(ArrayIndexOutOfBoundsException ex){

    System.out.println("Выход за пределы массива");

}

catch(NumberFormatException ex){

    System.out.println("Ошибка преобразования из строки в число");

}
```

Если у нас возникает исключение определенного типа, то оно переходит к соответствующему блоку catch.

**Оператор throw**

Чтобы сообщить о выполнении исключительных ситуаций в программе, можно использовать оператор **throw**. То есть с помощью этого оператора мы сами можем создать исключение и вызвать его в процессе выполнения. Например, в нашей программе происходит ввод числа, и мы хотим, чтобы, если число больше 30, то возникало исключение:

```java
package firstapp;

import java.util.Scanner;

public class FirstApp {

    public static void main(String[] args) {

        try{

            Scanner in = new Scanner(System.in);

            int x = in.nextInt();

            if(x>=30){

               throw new Exception("Число х должно быть меньше 30");

           }

        }

        catch(Exception ex){

            System.out.println(ex.getMessage());

        }

        System.out.println("Программа завершена");

    }  

}
```

Здесь для создания объекта исключения используется конструктор класса Exception, в который передается сообщение об исключении. И если число х окажется больше 29, то будет выброшено исключение и управление перейдет к блоку catch.

В блоке catch мы можем получить сообщение об исключении с помощью метода getMessage().